// Simple and robust error handling with error-chain!
// Use this as a template for new projects.

// `error_chain!` can recurse deeply
#![recursion_limit = "1024"]

// Import the macro
#[macro_use]
extern crate error_chain;

// We'll put our errors in an `errors` module, and other modules in
// this crate will `use errors::*;` to get access to everything
// `error_chain!` creates.
mod errors;

use errors::*;

fn main() {
    if let Err(ref e) = run() {
        println!("error: {}", e);

        for e in e.iter().skip(1) {
            println!("caused by: {}", e);
        }

        // The backtrace is not always generated. Try to run this example
        // with `RUST_BACKTRACE=1`.
        if let Some(backtrace) = e.backtrace() {
            println!("backtrace: {:?}", backtrace);
        }

        ::std::process::exit(1);
    }
}

// Most functions will return the `Result` type, imported from the
// `errors` module. It is a typedef of the standard `Result` type
// for which the error type is always our own `Error`.
fn run() -> Result<()> {
    use std::fs::File;

    // This operation will fail
    File::open("tretrete")
        .chain_err(|| "unable to open tretrete file")?;

    Ok(())
}

